Workbook
Name DENS_MAX: DENS!$N$23:$N$27
Name DENS_MAX: #REF!
Name DENSIDADE: [1]DENS1!$M$21:$M$26
Name Retido: #REF!
Name Retido: #REF!

Sheet DENS
B2: ENSAIO DE COMPACTAÇÃO
B3: INTERESSADO: | F3: OBRA: | K3: PROCTOR: | M3: REGISTRO Nº:
K5: PROFUNDIDADE (cm): | M5: DATA:
B7: PROCEDÊNCIA: | F7: CIDADE: | J7: RESPONSÁVEL:
B9: UMIDADE HIGROSCÓPICA | G9: % | H9: ENERGIA COMPACTAÇÃO / DADOS EQUIPAMENTO
B10: C Á P S U L A No | H10: MOLDE Nº | N10: 05
B11: P E S O B R U T O Ú M I D O - (g)
B12: P E S O B R U T O S E C O - (g) | H12: E N E R G I A DE C O M P A C T A Ç Ã O (Kg.Cm / Cm3) | N12: -
B13: T A R A D A C Á P S U L A - (g) | H13: ALTURA DE QUEDA DO SOQUETE - (Cm): | N13: -
B14: P E S O D A Á G U A - (g) | H14: V O L U M E D O M O L D E - (Cm3) | N14: 2.068
B15: P E S O D O S O L O S E C O - (g) | G15: =G12-G13 -> 0 | H15: P E S O D O M O L D E - (g) | N15: 5.414
B16: U M I D A D E - (%) | G16: =G14/G15*100 -> #DIV/0! | H16: P E S O D O S O Q U E T E - (g) | N16: 4.536
B17: U M I D A D E M É D I A - (%) | G17: =G16 -> #DIV/0! | H17: E S P E S S U R A D O D I S C O E S P A Ç A D O R - (pol) | N17: 2.5
B18: PONTO N o | C18: PESO BRUTO ÚMIDO | D18: PESO DO SOLO ÚMIDO | E18: DENSIDADE DO SOLO ÚMIDO | F18: D E T E R M I N A Ç Ã O D A U M I D A D E | M18: UMIDADE / MÉDIA | N18: DENSIDADE DO SOLO SECO
F19: CÁPSULAS N o | G19: P E S O B R U T O Ú M I D O | H19: P E S O B R U T O S E C O | I19: P E S O D A C Á P S U L A | J19: P E S O D A Á G U A | K19: P E S O D O S O L O S E C O | L19: U M I D A D E
B22: ------ | C22: g | D22: g | E22: g / Cm3 | F22: ------ | G22: g | H22: g | I22: g | J22: g | K22: g | L22: % | M22: % | N22: g / Cm3
B23: 1 | G23: =I23+J23+K23 -> 0 | H23: =I23+K23 -> 0 | L23: =J23/K23*100 -> #DIV/0! | M23: =L23 -> #DIV/0! | N23: =E23/(1+(M23/100)) -> #DIV/0!
B24: 2 | G24: =I24+J24+K24 -> 0 | H24: =I24+K24 -> 0 | L24: =J24/K24*100 -> #DIV/0! | M24: =L24 -> #DIV/0! | N24: =E24/(1+(M24/100)) -> #DIV/0!
B25: 3 | G25: =I25+J25+K25 -> 0 | H25: =I25+K25 -> 0 | L25: =J25/K25*100 -> #DIV/0! | M25: =L25 -> #DIV/0! | N25: =E25/(1+(M25/100)) -> #DIV/0!
B26: 4 | G26: =I26+J26+K26 -> 0 | H26: =I26+K26 -> 0 | L26: =J26/K26*100 -> #DIV/0! | M26: =L26 -> #DIV/0! | N26: =E26/(1+(M26/100)) -> #DIV/0!
B27: 5 | G27: =I27+J27+K27 -> 0 | H27: =I27+K27 -> 0 | L27: =J27/K27*100 -> #DIV/0! | M27: =L27 -> #DIV/0! | N27: =E27/(1+(M27/100)) -> #DIV/0!
L30: GOLPES POR CAMADA (Ud)
C31: Curva | E31: Vertical | H31: HORIZONTAL
B32: =Calc!K147 -> #DIV/0! | C32: =Calc!L147 -> #DIV/0! | E32: =Calc!E147 -> #DIV/0! | F32: =Calc!F147 -> 0 | H32: =Calc!H147 -> #DIV/0! | I32: =Calc!I147 -> #DIV/0!
B33: =Calc!K148 -> #DIV/0! | C33: =Calc!L148 -> #DIV/0! | E33: =Calc!E148 -> #DIV/0! | F33: =Calc!F148 -> #DIV/0! | H33: =Calc!H148 -> #DIV/0! | I33: =Calc!I148 -> #DIV/0!
B34: =Calc!K149 -> #DIV/0! | C34: =Calc!L149 -> #DIV/0! | E34: =Calc!E149 -> #DIV/0! | F34: =Calc!F149 -> #DIV/0! | H34: =Calc!H149 -> #DIV/0! | I34: =Calc!I149 -> #DIV/0! | M34: 26
B35: =Calc!K150 -> #DIV/0! | C35: =Calc!L150 -> #DIV/0! | E35: =Calc!E150 -> #DIV/0! | F35: =Calc!F150 -> #DIV/0! | H35: =Calc!H150 -> #DIV/0! | I35: =Calc!I150 -> #DIV/0!
B36: =Calc!K151 -> #REF! | C36: =Calc!L151 -> #REF! | E36: =Calc!E151 -> #DIV/0! | F36: =Calc!F151 -> #DIV/0! | H36: =Calc!H151 -> #DIV/0! | I36: =Calc!I151 -> #DIV/0! | L36: NÚMERO DE CAMADAS (Ud)
M40: 5
L42: DENSIDADE MÁXIMA (g/cm³)
M46: =N25 -> #DIV/0!
L49: UMIDADE ÓTIMA (%)
M53: =M25 -> #DIV/0!
L55: TEMPO DE ENSAIO
L56: INÍCIO:
B58: OBSERVAÇÕES:

Sheet CBR
B2: DETERMINAÇÃO DO ÍNDICE SUPORTE CALIFORNIA I.S.C
B3: =DENS!B3 -> INTERESSADO: | F3: =DENS!F3 -> OBRA: | L3: PROCTOR: | O3: REGISTRO Nº
B4: =DENS!B4 | F4: =DENS!F4 | L4: =DENS!K4 | O4: -
B5: =DENS!#REF! -> #REF! | I5: LOCAL: FURO / ESTACA | K5: LOCAL: FURO / ESTACA | M5: PROFUNDIDADE (cm) | O5: DATA:
B6: =DENS!B6 -> 0 | I6: =DENS!H6 -> 0 | M6: =DENS!K6 | O6: =DENS!M6 -> 0
B7: PROCEDÊNCIA: | H7: CIDADE: | L7: RESPONSÁVEL:
B8: =DENS!$B$8 | H8: =DENS!F8 | L8: =DENS!J8
B9: M O L D A G E M DO C O R P O D E P R O V A
B10: E Q U I P A M E N T O S - D A D O S | J10: U M I D A D E S | O10: HIGROSCÓPICA | P10: MOLDAGEM
B11: Molde - Nº | H11: 02 | J11: Cápsula - No
B12: Peso do Molde | H12: 5436 | J12: Peso Bruto Úmido
B13: Volume do Molde | H13: 3210 | J13: Peso Bruto Seco
B14: Nº de Camadas | H14: 5 | J14: Peso da Cápsula
B15: Golpes/Camada | H15: 26 | J15: Peso da Água | O15: =O12-O13 -> 0 | P15: =P12-P13 -> 0
B16: Peso do Soquete | H16: 4536 | J16: Peso do Solo Seco | O16: =O13-O14 -> 0 | P16: =P13-P14 -> 0
B17: Espessura do disco espaçador | H17: 2½" | J17: Umidade (%) | O17: =O15/O16*100 -> #DIV/0! | P17: =P15/P16*100 -> #DIV/0!
B18: Altura do Cilindro | H18: 114 | J18: Umidade Média (%) | O18: =O17 -> #DIV/0! | P18: =P17 -> #DIV/0!
B19: DADOS DE COMPACTAÇÃO | H19: CÁLCULO DA ÁGUA A JUNTAR | O19: Volume Calc. (cm³) | P19: Constante Prensa
B20: Densidade Máxima - kg/m³ | F20: =DENS!M46 -> #DIV/0! | H20: Peso do Solo Úmido Passando na peneira n° 04
B21: Umidade Ótima - % | H21: Peso do Solo Seco Passando na peneira n° 04 | M21: =M20/(1+(O18/100)) -> #DIV/0! | O21: =IF(OR(M21="",F23=""),"",M21*F23/100) -> #DIV/0! | P21: N°
B22: Umidade Higroscópica - % | F22: =O17 -> #DIV/0! | H22: Peso do Pedregulho Retido na peneira nº 04 | M22: =(M20-M21)*100 -> #DIV/0! | O22: =IF(M22="","",M22*2%) -> #DIV/0! | P22: 0.0839
B23: Diferença de Umidade - % | F23: =F21-F22 -> #DIV/0! | H23: Água a Juntar: | J23: =M21*(F23)*10 -> #DIV/0! | O23: =IF(OR(O21="",O22=""),"",O21+O22) -> #DIV/0!
B24: E N S A I O D E P E N E T R A Ç Ã O | L24: E X P A N S Ã O | P24: =J34 -> 0
B25: Tempo min. | D25: Penetração | F25: Leitura Extens. | G25: Pressão - kg/cm² | L25: Datas | N25: Leitura Defl. (mm) | O25: Diferença (mm) | P25: Expansão %
D26: Pol. | E26: mm | G26: Calc. | H26: Corrig. | I26: Padrão | J26: % | L26: Dia | M26: Hora
B27: 30 seg. | D27: 0.025 | E27: 0.63 | L27: 46170 | M27: 24h | N27: 0 | P27: =IF(OR(O27="",$H$18=""),"",(O27/$H$18)*100)
D28: 0.05 | E28: 1.27
B29: 2 | D29: 0.1 | E29: 2.54 | I29: 70 | L29: =L27+1 -> 46171 | M29: 48h
B30: 4 | D30: 0.2 | E30: 5.08 | I30: 105
B31: 6 | D31: 0.3 | E31: 7.62 | I31: 133 | L31: =L29+1 -> 46172 | M31: 72h
B32: 8 | D32: 0.4 | E32: 10.16 | I32: 161
B33: 10 | D33: 0.5 | E33: 12.7 | G33: =IF(F33="","",F33*$P$22) | L33: =L31+1 -> 46173 | M33: 96h | P33: =N33 -> 0
E34: CBR = | F34: =MAX(J29:J30)/100 -> 0 | H34: EXPANSÃO (%) = | J34: =IF(P33="","",P33/100) -> 0
M35: CÁLCULOS PARA MOLDAGEM DO C.P.
G36: 0 | H36: 0 | M36: Peso do solo úmido - Ph (g) =
G37: =D27 -> 0.025 | H37: =G27 -> 0
G38: =D28 -> 0.05 | H38: =G28 -> 0 | M38: Peso retido na # n° 04 - Pr 4 (g) =
G39: =D29 -> 0.1 | H39: =G29 -> 0
G40: =D30 -> 0.2 | H40: =G30 -> 0 | M40: Peso passando n # n° 04 - Os 4 (g) =
H41: =G31 -> 0
...

Sheet Calc
C2: Método dos Mínimos Quadrados:
E5: Y= a x4 + b x3 + c x2 + d x + e
B7: a0 = a | C7: a1 = b | D7: a2 = c | E7: a3 = b | F7: a4 = e
B8: g0(x) = x4 | C8: g1(x) = x3 | D8: g2(x) = x2 | E8: g3(x) = x | F8: g4(x) = 1 | G8: 1
C11: Tabela
C13: x | D13: =DENS!M23 -> #DIV/0! | E13: =DENS!M24 -> #DIV/0! | F13: =DENS!M25 -> #DIV/0! | G13: =DENS!M26 -> #DIV/0! | H13: =DENS!#REF! -> #REF!
C14: f(x) | D14: =DENS!N23 -> #DIV/0! | E14: =DENS!N24 -> #DIV/0! | F14: =DENS!N25 -> #DIV/0! | G14: =DENS!N26 -> #DIV/0! | H14: =DENS!#REF! -> #REF!
B17: i | C17: x | D17: f(x) | E17: g0(x) | F17: g1(x) | G17: g2(x) | H17: g3(x) | I17: g4(x) | J17: g02(x) | K17: g12(x) | L17: g22(x) | M17: g32(x) | N17: g42(x) | O17: g0(x).g1(x) | P17: g0(x).g2(x) | Q17: g0(x).g3(x) | R17: g0(x).g4(x) | S17: g1(x).g2(x) | T17: g1(x).g3(x) | U17: g1(x).g4(x) | V17: g2(x).g3(x) | W17: g2(x).g4(x) | X17: g3(x).g4(x) | Y17: g0(x).f(x) | Z17: g1(x).f(x) | AA17: g2(x).f(x) | AB17: g3(x).f(x) | AC17: g4(x).f(x)
B18: 0 | C18: =D13 -> #DIV/0! | D18: =D$14 -> #DIV/0! | E18: =C18^4 -> #DIV/0! | F18: =C18^3 -> #DIV/0! | G18: =C18^2 -> #DIV/0! | H18: =C18 -> #DIV/0! | I18: =1 -> 1 | J18: =E18^2 -> #DIV/0! | K18: =F18^2 -> #DIV/0! | L18: =G18^2 -> #DIV/0! | M18: =H18^2 -> #DIV/0! | N18: =I18^2 -> 1 | O18: =E18*F18 -> #DIV/0! | P18: =E18*G18 -> #DIV/0! | Q18: =E18*H18 -> #DIV/0! | R18: =E18*I18 -> #DIV/0! | S18: =F18*G18 -> #DIV/0! | T18: =F18*H18 -> #DIV/0! | U18: =F18*I18 -> #DIV/0! | V18: =G18*H18 -> #DIV/0! | W18: =G18*I18 -> #DIV/0! | X18: =H18*I18 -> #DIV/0! | Y18: =E18*D18 -> #DIV/0! | Z18: =D18*F18 -> #DIV/0! | AA18: =G18*D18 -> #DIV/0! | AB18: =H18*D18 -> #DIV/0! | AC18: =D18*I18 -> #DIV/0!
B19: 1 | C19: =E13 -> #DIV/0! | D19: =E14 -> #DIV/0! | E19: =C19^4 -> #DIV/0! | F19: =C19^3 -> #DIV/0! | G19: =C19^2 -> #DIV/0! | H19: =C19 -> #DIV/0! | I19: =1 -> 1 | J19: =E19^2 -> #DIV/0! | K19: =F19^2 -> #DIV/0! | L19: =G19^2 -> #DIV/0! | M19: =H19^2 -> #DIV/0! | N19: =I19^2 -> 1 | O19: =E19*F19 -> #DIV/0! | P19: =E19*G19 -> #DIV/0! | Q19: =E19*H19 -> #DIV/0! | R19: =E19*I19 -> #DIV/0! | S19: =F19*G19 -> #DIV/0! | T19: =F19*H19 -> #DIV/0! | U19: =F19*I19 -> #DIV/0! | V19: =G19*H19 -> #DIV/0! | W19: =G19*I19 -> #DIV/0! | X19: =H19*I19 -> #DIV/0! | Y19: =E19*D19 -> #DIV/0! | Z19: =D19*F19 -> #DIV/0! | AA19: =G19*D19 -> #DIV/0! | AB19: =H19*D19 -> #DIV/0! | AC19: =D19*I19 -> #DIV/0!
B20: 2 | C20: =F13 -> #DIV/0! | D20: =F14 -> #DIV/0! | E20: =C20^4 -> #DIV/0! | F20: =C20^3 -> #DIV/0! | G20: =C20^2 -> #DIV/0! | H20: =C20 -> #DIV/0! | I20: =1 -> 1 | J20: =E20^2 -> #DIV/0! | K20: =F20^2 -> #DIV/0! | L20: =G20^2 -> #DIV/0! | M20: =H20^2 -> #DIV/0! | N20: =I20^2 -> 1 | O20: =E20*F20 -> #DIV/0! | P20: =E20*G20 -> #DIV/0! | Q20: =E20*H20 -> #DIV/0! | R20: =E20*I20 -> #DIV/0! | S20: =F20*G20 -> #DIV/0! | T20: =F20*H20 -> #DIV/0! | U20: =F20*I20 -> #DIV/0! | V20: =G20*H20 -> #DIV/0! | W20: =G20*I20 -> #DIV/0! | X20: =H20*I20 -> #DIV/0! | Y20: =E20*D20 -> #DIV/0! | Z20: =D20*F20 -> #DIV/0! | AA20: =G20*D20 -> #DIV/0! | AB20: =H20*D20 -> #DIV/0! | AC20: =D20*I20 -> #DIV/0!
B21: 3 | C21: =G13 -> #DIV/0! | D21: =G14 -> #DIV/0! | E21: =C21^4 -> #DIV/0! | F21: =C21^3 -> #DIV/0! | G21: =C21^2 -> #DIV/0! | H21: =C21 -> #DIV/0! | I21: =1 -> 1 | J21: =E21^2 -> #DIV/0! | K21: =F21^2 -> #DIV/0! | L21: =G21^2 -> #DIV/0! | M21: =H21^2 -> #DIV/0! | N21: =I21^2 -> 1 | O21: =E21*F21 -> #DIV/0! | P21: =E21*G21 -> #DIV/0! | Q21: =E21*H21 -> #DIV/0! | R21: =E21*I21 -> #DIV/0! | S21: =F21*G21 -> #DIV/0! | T21: =F21*H21 -> #DIV/0! | U21: =F21*I21 -> #DIV/0! | V21: =G21*H21 -> #DIV/0! | W21: =G21*I21 -> #DIV/0! | X21: =H21*I21 -> #DIV/0! | Y21: =E21*D21 -> #DIV/0! | Z21: =D21*F21 -> #DIV/0! | AA21: =G21*D21 -> #DIV/0! | AB21: =H21*D21 -> #DIV/0! | AC21: =D21*I21 -> #DIV/0!
B22: 4 | C22: =H13 -> #REF! | D22: =H14 -> #REF! | E22: =C22^4 -> #REF! | F22: =C22^3 -> #REF! | G22: =C22^2 -> #REF! | H22: =C22 -> #REF! | I22: =1 -> 1 | J22: =E22^2 -> #REF! | K22: =F22^2 -> #REF! | L22: =G22^2 -> #REF! | M22: =H22^2 -> #REF! | N22: =I22^2 -> 1 | O22: =E22*F22 -> #REF! | P22: =E22*G22 -> #REF! | Q22: =E22*H22 -> #REF! | R22: =E22*I22 -> #REF! | S22: =F22*G22 -> #REF! | T22: =F22*H22 -> #REF! | U22: =F22*I22 -> #REF! | V22: =G22*H22 -> #REF! | W22: =G22*I22 -> #REF! | X22: =H22*I22 -> #REF! | Y22: =E22*D22 -> #REF! | Z22: =D22*F22 -> #REF! | AA22: =G22*D22 -> #REF! | AB22: =H22*D22 -> #REF! | AC22: =D22*I22 -> #REF!
I23: å = | J23: =SUM(J18:J22) -> #DIV/0! | K23: =SUM(K18:K22) -> #DIV/0! | L23: =SUM(L18:L22) -> #DIV/0! | M23: =SUM(M18:M22) -> #DIV/0! | N23: =SUM(N18:N22) -> 5 | O23: =SUM(O18:O22) -> #DIV/0! | P23: =SUM(P18:P22) -> #DIV/0! | Q23: =SUM(Q18:Q22) -> #DIV/0! | ... AC23: =SUM(AC18:AC22) -> #DIV/0!
E28: Sistema Linear:
F31: =J23 -> #DIV/0! | G31: =O23 -> #DIV/0! | H31: =P23 -> #DIV/0! | I31: =Q23 -> #DIV/0! | J31: =R23 -> #DIV/0! | L31: a0 | N31: =Y23 -> #DIV/0!
F32: =O23 -> #DIV/0! | G32: =K23 -> #DIV/0! | H32: =S23 -> #DIV/0! | I32: =T23 -> #DIV/0! | J32: =U23 -> #DIV/0! | L32: a1 | N32: =Z23 -> #DIV/0!
E33: A | F33: =P23 -> #DIV/0! | G33: =S23 -> #DIV/0! | H33: =L23 -> #DIV/0! | I33: =V23 -> #DIV/0! | J33: =W23 -> #DIV/0! | K33: x | L33: a2 | M33: = | N33: =AA23 -> #DIV/0!
F34: =Q23 -> #DIV/0! | G34: =T23 -> #DIV/0! | H34: =V23 -> #DIV/0! | I34: =M23 -> #DIV/0! | J34: =X23 -> #DIV/0! | L34: a3 | N34: =AB23 -> #DIV/0!
F35: =R23 -> #DIV/0! | G35: =U23 -> #DIV/0! | H35: =W23 -> #DIV/0! | I35: =X23 -> #DIV/0! | J35: =N23 -> 5 | L35: a4 | N35: =AC23 -> #DIV/0!
F37: =N31 -> #DIV/0! | G37: =G31 -> #DIV/0! | H37: =H31 -> #DIV/0! | I37: =I31 -> #DIV/0! | J37: =J31 -> #DIV/0!
F38: =N32 -> #DIV/0! | G38: =G32 -> #DIV/0! | H38: =H32 -> #DIV/0! | I38: =I32 -> #DIV/0! | J38: =J32 -> #DIV/0!
E39: A0 = | F39: =N33 -> #DIV/0! | G39: =G33 -> #DIV/0! | H39: =H33 -> #DIV/0! | I39: =I33 -> #DIV/0! | J39: =J33 -> #DIV/0!
F40: =N34 -> #DIV/0! | G40: =G34 -> #DIV/0! | H40: =H34 -> #DIV/0! | I40: =I34 -> #DIV/0! | J40: =J34 -> #DIV/0!
F41: =N35 -> #DIV/0! | G41: =G35 -> #DIV/0! | H41: =H35 -> #DIV/0! | I41: =I35 -> #DIV/0! | J41: =J35 -> 5
F43: =F31 -> #DIV/0! | G43: =N31 -> #DIV/0! | H43: =H31 -> #DIV/0! | I43: =I31 -> #DIV/0! | J43: =J31 -> #DIV/0!
F44: =F32 -> #DIV/0! | G44: =N32 -> #DIV/0! | H44: =H32 -> #DIV/0! | I44: =I32 -> #DIV/0! | J44: =J32 -> #DIV/0!
E45: A1= | F45: =F33 -> #DIV/0! | G45: =N33 -> #DIV/0! | H45: =H33 -> #DIV/0! | I45: =I33 -> #DIV/0! | J45: =J33 -> #DIV/0!
F46: =F34 -> #DIV/0! | G46: =N34 -> #DIV/0! | H46: =H34 -> #DIV/0! | I46: =I34 -> #DIV/0! | J46: =J34 -> #DIV/0!
F47: =F35 -> #DIV/0! | G47: =N35 -> #DIV/0! | H47: =H35 -> #DIV/0! | I47: =I35 -> #DIV/0! | J47: =J35 -> 5
F49: =F31 -> #DIV/0! | G49: =G31 -> #DIV/0! | H49: =N31 -> #DIV/0! | I49: =I31 -> #DIV/0! | J49: =J31 -> #DIV/0!
F50: =F32 -> #DIV/0! | G50: =G32 -> #DIV/0! | H50: =N32 -> #DIV/0! | I50: =I32 -> #DIV/0! | J50: =J32 -> #DIV/0!
E51: A2= | F51: =F33 -> #DIV/0! | G51: =G33 -> #DIV/0! | H51: =N33 -> #DIV/0! | I51: =I33 -> #DIV/0! | J51: =J33 -> #DIV/0!
F52: =F34 -> #DIV/0! | G52: =G34 -> #DIV/0! | H52: =N34 -> #DIV/0! | I52: =I34 -> #DIV/0! | J52: =J34 -> #DIV/0!
F53: =F35 -> #DIV/0! | G53: =G35 -> #DIV/0! | H53: =N35 -> #DIV/0! | I53: =I35 -> #DIV/0! | J53: =J35 -> 5
F55: =F31 -> #DIV/0! | G55: =G31 -> #DIV/0! | H55: =H31 -> #DIV/0! | I55: =N31 -> #DIV/0! | J55: =J31 -> #DIV/0!
F56: =F32 -> #DIV/0! | G56: =G32 -> #DIV/0! | H56: =H32 -> #DIV/0! | I56: =N32 -> #DIV/0! | J56: =J32 -> #DIV/0!
E57: A3= | F57: =F33 -> #DIV/0! | G57: =G33 -> #DIV/0! | H57: =H33 -> #DIV/0! | I57: =N33 -> #DIV/0! | J57: =J33 -> #DIV/0!
F58: =F34 -> #DIV/0! | G58: =G34 -> #DIV/0! | H58: =H34 -> #DIV/0! | I58: =N34 -> #DIV/0! | J58: =J34 -> #DIV/0!
F59: =F35 -> #DIV/0! | G59: =G35 -> #DIV/0! | H59: =H35 -> #DIV/0! | I59: =N35 -> #DIV/0! | J59: =J35 -> 5
...
